<?xml version="1.0" encoding="UTF-8"?>
<testng-results skipped="8" failed="2" total="11" passed="1">
  <reporter-output>
  </reporter-output>
  <suite name="Suite" duration-ms="70" started-at="2020-04-04T19:54:27Z" finished-at="2020-04-04T19:54:27Z">
    <groups>
    </groups>
    <test name="Test" duration-ms="70" started-at="2020-04-04T19:54:27Z" finished-at="2020-04-04T19:54:27Z">
      <class name="retryLogicFailed.retryFailedTest">
        <test-method status="PASS" signature="bMethod()[pri:0, instance:retryLogicFailed.retryFailedTest@3884b2]" name="bMethod" is-config="true" duration-ms="6" started-at="2020-04-05T01:24:27Z" finished-at="2020-04-05T01:24:27Z">
          <reporter-output>
          </reporter-output>
        </test-method> <!-- bMethod -->
        <test-method status="SKIP" signature="homepageTest()[pri:0, instance:retryLogicFailed.retryFailedTest@3884b2]" name="homepageTest" duration-ms="8" started-at="2020-04-05T01:24:27Z" finished-at="2020-04-05T01:24:27Z">
          <exception class="java.lang.AssertionError">
            <message>
              <![CDATA[expected [true] but found [false]]]>
            </message>
            <full-stacktrace>
              <![CDATA[java.lang.AssertionError: expected [true] but found [false]
	at org.testng.Assert.fail(Assert.java:94)
	at org.testng.Assert.failNotEquals(Assert.java:496)
	at org.testng.Assert.assertTrue(Assert.java:42)
	at org.testng.Assert.assertTrue(Assert.java:52)
	at retryLogicFailed.retryFailedTest.homepageTest(retryFailedTest.java:19)
	at sun.reflect.NativeMethodAccessorImpl.invoke0(Native Method)
	at sun.reflect.NativeMethodAccessorImpl.invoke(Unknown Source)
	at sun.reflect.DelegatingMethodAccessorImpl.invoke(Unknown Source)
	at java.lang.reflect.Method.invoke(Unknown Source)
	at org.testng.internal.MethodInvocationHelper.invokeMethod(MethodInvocationHelper.java:85)
	at org.testng.internal.Invoker.invokeMethod(Invoker.java:639)
	at org.testng.internal.Invoker.invokeTestMethod(Invoker.java:816)
	at org.testng.internal.Invoker.invokeTestMethods(Invoker.java:1124)
	at org.testng.internal.TestMethodWorker.invokeTestMethods(TestMethodWorker.java:125)
	at org.testng.internal.TestMethodWorker.run(TestMethodWorker.java:108)
	at org.testng.TestRunner.privateRun(TestRunner.java:774)
	at org.testng.TestRunner.run(TestRunner.java:624)
	at org.testng.SuiteRunner.runTest(SuiteRunner.java:359)
	at org.testng.SuiteRunner.runSequentially(SuiteRunner.java:354)
	at org.testng.SuiteRunner.privateRun(SuiteRunner.java:312)
	at org.testng.SuiteRunner.run(SuiteRunner.java:261)
	at org.testng.SuiteRunnerWorker.runSuite(SuiteRunnerWorker.java:52)
	at org.testng.SuiteRunnerWorker.run(SuiteRunnerWorker.java:86)
	at org.testng.TestNG.runSuitesSequentially(TestNG.java:1215)
	at org.testng.TestNG.runSuitesLocally(TestNG.java:1140)
	at org.testng.TestNG.run(TestNG.java:1048)
	at org.testng.remote.AbstractRemoteTestNG.run(AbstractRemoteTestNG.java:126)
	at org.testng.remote.RemoteTestNG.initAndRun(RemoteTestNG.java:152)
	at org.testng.remote.RemoteTestNG.main(RemoteTestNG.java:57)
]]>
            </full-stacktrace>
          </exception> <!-- java.lang.AssertionError -->
          <reporter-output>
          </reporter-output>
        </test-method> <!-- homepageTest -->
        <test-method status="PASS" signature="bMethod()[pri:0, instance:retryLogicFailed.retryFailedTest@3884b2]" name="bMethod" is-config="true" duration-ms="0" started-at="2020-04-05T01:24:27Z" finished-at="2020-04-05T01:24:27Z">
          <reporter-output>
          </reporter-output>
        </test-method> <!-- bMethod -->
        <test-method status="SKIP" signature="homepageTest()[pri:0, instance:retryLogicFailed.retryFailedTest@3884b2]" name="homepageTest" duration-ms="1" started-at="2020-04-05T01:24:27Z" finished-at="2020-04-05T01:24:27Z">
          <exception class="java.lang.AssertionError">
            <message>
              <![CDATA[expected [true] but found [false]]]>
            </message>
            <full-stacktrace>
              <![CDATA[java.lang.AssertionError: expected [true] but found [false]
	at org.testng.Assert.fail(Assert.java:94)
	at org.testng.Assert.failNotEquals(Assert.java:496)
	at org.testng.Assert.assertTrue(Assert.java:42)
	at org.testng.Assert.assertTrue(Assert.java:52)
	at retryLogicFailed.retryFailedTest.homepageTest(retryFailedTest.java:19)
	at sun.reflect.NativeMethodAccessorImpl.invoke0(Native Method)
	at sun.reflect.NativeMethodAccessorImpl.invoke(Unknown Source)
	at sun.reflect.DelegatingMethodAccessorImpl.invoke(Unknown Source)
	at java.lang.reflect.Method.invoke(Unknown Source)
	at org.testng.internal.MethodInvocationHelper.invokeMethod(MethodInvocationHelper.java:85)
	at org.testng.internal.Invoker.invokeMethod(Invoker.java:639)
	at org.testng.internal.Invoker.retryFailed(Invoker.java:963)
	at org.testng.internal.Invoker.invokeTestMethods(Invoker.java:1142)
	at org.testng.internal.TestMethodWorker.invokeTestMethods(TestMethodWorker.java:125)
	at org.testng.internal.TestMethodWorker.run(TestMethodWorker.java:108)
	at org.testng.TestRunner.privateRun(TestRunner.java:774)
	at org.testng.TestRunner.run(TestRunner.java:624)
	at org.testng.SuiteRunner.runTest(SuiteRunner.java:359)
	at org.testng.SuiteRunner.runSequentially(SuiteRunner.java:354)
	at org.testng.SuiteRunner.privateRun(SuiteRunner.java:312)
	at org.testng.SuiteRunner.run(SuiteRunner.java:261)
	at org.testng.SuiteRunnerWorker.runSuite(SuiteRunnerWorker.java:52)
	at org.testng.SuiteRunnerWorker.run(SuiteRunnerWorker.java:86)
	at org.testng.TestNG.runSuitesSequentially(TestNG.java:1215)
	at org.testng.TestNG.runSuitesLocally(TestNG.java:1140)
	at org.testng.TestNG.run(TestNG.java:1048)
	at org.testng.remote.AbstractRemoteTestNG.run(AbstractRemoteTestNG.java:126)
	at org.testng.remote.RemoteTestNG.initAndRun(RemoteTestNG.java:152)
	at org.testng.remote.RemoteTestNG.main(RemoteTestNG.java:57)
]]>
            </full-stacktrace>
          </exception> <!-- java.lang.AssertionError -->
          <reporter-output>
          </reporter-output>
        </test-method> <!-- homepageTest -->
        <test-method status="PASS" signature="aMethod()[pri:0, instance:retryLogicFailed.retryFailedTest@3884b2]" name="aMethod" is-config="true" duration-ms="0" started-at="2020-04-05T01:24:27Z" finished-at="2020-04-05T01:24:27Z">
          <reporter-output>
          </reporter-output>
        </test-method> <!-- aMethod -->
        <test-method status="PASS" signature="bMethod()[pri:0, instance:retryLogicFailed.retryFailedTest@3884b2]" name="bMethod" is-config="true" duration-ms="0" started-at="2020-04-05T01:24:27Z" finished-at="2020-04-05T01:24:27Z">
          <reporter-output>
          </reporter-output>
        </test-method> <!-- bMethod -->
        <test-method status="SKIP" signature="homepageTest()[pri:0, instance:retryLogicFailed.retryFailedTest@3884b2]" name="homepageTest" duration-ms="2" started-at="2020-04-05T01:24:27Z" finished-at="2020-04-05T01:24:27Z">
          <exception class="java.lang.AssertionError">
            <message>
              <![CDATA[expected [true] but found [false]]]>
            </message>
            <full-stacktrace>
              <![CDATA[java.lang.AssertionError: expected [true] but found [false]
	at org.testng.Assert.fail(Assert.java:94)
	at org.testng.Assert.failNotEquals(Assert.java:496)
	at org.testng.Assert.assertTrue(Assert.java:42)
	at org.testng.Assert.assertTrue(Assert.java:52)
	at retryLogicFailed.retryFailedTest.homepageTest(retryFailedTest.java:19)
	at sun.reflect.NativeMethodAccessorImpl.invoke0(Native Method)
	at sun.reflect.NativeMethodAccessorImpl.invoke(Unknown Source)
	at sun.reflect.DelegatingMethodAccessorImpl.invoke(Unknown Source)
	at java.lang.reflect.Method.invoke(Unknown Source)
	at org.testng.internal.MethodInvocationHelper.invokeMethod(MethodInvocationHelper.java:85)
	at org.testng.internal.Invoker.invokeMethod(Invoker.java:639)
	at org.testng.internal.Invoker.retryFailed(Invoker.java:963)
	at org.testng.internal.Invoker.invokeTestMethods(Invoker.java:1142)
	at org.testng.internal.TestMethodWorker.invokeTestMethods(TestMethodWorker.java:125)
	at org.testng.internal.TestMethodWorker.run(TestMethodWorker.java:108)
	at org.testng.TestRunner.privateRun(TestRunner.java:774)
	at org.testng.TestRunner.run(TestRunner.java:624)
	at org.testng.SuiteRunner.runTest(SuiteRunner.java:359)
	at org.testng.SuiteRunner.runSequentially(SuiteRunner.java:354)
	at org.testng.SuiteRunner.privateRun(SuiteRunner.java:312)
	at org.testng.SuiteRunner.run(SuiteRunner.java:261)
	at org.testng.SuiteRunnerWorker.runSuite(SuiteRunnerWorker.java:52)
	at org.testng.SuiteRunnerWorker.run(SuiteRunnerWorker.java:86)
	at org.testng.TestNG.runSuitesSequentially(TestNG.java:1215)
	at org.testng.TestNG.runSuitesLocally(TestNG.java:1140)
	at org.testng.TestNG.run(TestNG.java:1048)
	at org.testng.remote.AbstractRemoteTestNG.run(AbstractRemoteTestNG.java:126)
	at org.testng.remote.RemoteTestNG.initAndRun(RemoteTestNG.java:152)
	at org.testng.remote.RemoteTestNG.main(RemoteTestNG.java:57)
]]>
            </full-stacktrace>
          </exception> <!-- java.lang.AssertionError -->
          <reporter-output>
          </reporter-output>
        </test-method> <!-- homepageTest -->
        <test-method status="PASS" signature="aMethod()[pri:0, instance:retryLogicFailed.retryFailedTest@3884b2]" name="aMethod" is-config="true" duration-ms="0" started-at="2020-04-05T01:24:27Z" finished-at="2020-04-05T01:24:27Z">
          <reporter-output>
          </reporter-output>
        </test-method> <!-- aMethod -->
        <test-method status="PASS" signature="aMethod()[pri:0, instance:retryLogicFailed.retryFailedTest@3884b2]" name="aMethod" is-config="true" duration-ms="1" started-at="2020-04-05T01:24:27Z" finished-at="2020-04-05T01:24:27Z">
          <reporter-output>
          </reporter-output>
        </test-method> <!-- aMethod -->
        <test-method status="SKIP" signature="homepageTest()[pri:0, instance:retryLogicFailed.retryFailedTest@3884b2]" name="homepageTest" duration-ms="2" started-at="2020-04-05T01:24:27Z" finished-at="2020-04-05T01:24:27Z">
          <exception class="java.lang.AssertionError">
            <message>
              <![CDATA[expected [true] but found [false]]]>
            </message>
            <full-stacktrace>
              <![CDATA[java.lang.AssertionError: expected [true] but found [false]
	at org.testng.Assert.fail(Assert.java:94)
	at org.testng.Assert.failNotEquals(Assert.java:496)
	at org.testng.Assert.assertTrue(Assert.java:42)
	at org.testng.Assert.assertTrue(Assert.java:52)
	at retryLogicFailed.retryFailedTest.homepageTest(retryFailedTest.java:19)
	at sun.reflect.NativeMethodAccessorImpl.invoke0(Native Method)
	at sun.reflect.NativeMethodAccessorImpl.invoke(Unknown Source)
	at sun.reflect.DelegatingMethodAccessorImpl.invoke(Unknown Source)
	at java.lang.reflect.Method.invoke(Unknown Source)
	at org.testng.internal.MethodInvocationHelper.invokeMethod(MethodInvocationHelper.java:85)
	at org.testng.internal.Invoker.invokeMethod(Invoker.java:639)
	at org.testng.internal.Invoker.retryFailed(Invoker.java:963)
	at org.testng.internal.Invoker.invokeTestMethods(Invoker.java:1142)
	at org.testng.internal.TestMethodWorker.invokeTestMethods(TestMethodWorker.java:125)
	at org.testng.internal.TestMethodWorker.run(TestMethodWorker.java:108)
	at org.testng.TestRunner.privateRun(TestRunner.java:774)
	at org.testng.TestRunner.run(TestRunner.java:624)
	at org.testng.SuiteRunner.runTest(SuiteRunner.java:359)
	at org.testng.SuiteRunner.runSequentially(SuiteRunner.java:354)
	at org.testng.SuiteRunner.privateRun(SuiteRunner.java:312)
	at org.testng.SuiteRunner.run(SuiteRunner.java:261)
	at org.testng.SuiteRunnerWorker.runSuite(SuiteRunnerWorker.java:52)
	at org.testng.SuiteRunnerWorker.run(SuiteRunnerWorker.java:86)
	at org.testng.TestNG.runSuitesSequentially(TestNG.java:1215)
	at org.testng.TestNG.runSuitesLocally(TestNG.java:1140)
	at org.testng.TestNG.run(TestNG.java:1048)
	at org.testng.remote.AbstractRemoteTestNG.run(AbstractRemoteTestNG.java:126)
	at org.testng.remote.RemoteTestNG.initAndRun(RemoteTestNG.java:152)
	at org.testng.remote.RemoteTestNG.main(RemoteTestNG.java:57)
]]>
            </full-stacktrace>
          </exception> <!-- java.lang.AssertionError -->
          <reporter-output>
          </reporter-output>
        </test-method> <!-- homepageTest -->
        <test-method status="PASS" signature="bMethod()[pri:0, instance:retryLogicFailed.retryFailedTest@3884b2]" name="bMethod" is-config="true" duration-ms="0" started-at="2020-04-05T01:24:27Z" finished-at="2020-04-05T01:24:27Z">
          <reporter-output>
          </reporter-output>
        </test-method> <!-- bMethod -->
        <test-method status="PASS" signature="bMethod()[pri:0, instance:retryLogicFailed.retryFailedTest@3884b2]" name="bMethod" is-config="true" duration-ms="0" started-at="2020-04-05T01:24:27Z" finished-at="2020-04-05T01:24:27Z">
          <reporter-output>
          </reporter-output>
        </test-method> <!-- bMethod -->
        <test-method status="PASS" signature="aMethod()[pri:0, instance:retryLogicFailed.retryFailedTest@3884b2]" name="aMethod" is-config="true" duration-ms="0" started-at="2020-04-05T01:24:27Z" finished-at="2020-04-05T01:24:27Z">
          <reporter-output>
          </reporter-output>
        </test-method> <!-- aMethod -->
        <test-method status="FAIL" signature="homepageTest()[pri:0, instance:retryLogicFailed.retryFailedTest@3884b2]" name="homepageTest" duration-ms="1" started-at="2020-04-05T01:24:27Z" finished-at="2020-04-05T01:24:27Z">
          <exception class="java.lang.AssertionError">
            <message>
              <![CDATA[expected [true] but found [false]]]>
            </message>
            <full-stacktrace>
              <![CDATA[java.lang.AssertionError: expected [true] but found [false]
	at org.testng.Assert.fail(Assert.java:94)
	at org.testng.Assert.failNotEquals(Assert.java:496)
	at org.testng.Assert.assertTrue(Assert.java:42)
	at org.testng.Assert.assertTrue(Assert.java:52)
	at retryLogicFailed.retryFailedTest.homepageTest(retryFailedTest.java:19)
	at sun.reflect.NativeMethodAccessorImpl.invoke0(Native Method)
	at sun.reflect.NativeMethodAccessorImpl.invoke(Unknown Source)
	at sun.reflect.DelegatingMethodAccessorImpl.invoke(Unknown Source)
	at java.lang.reflect.Method.invoke(Unknown Source)
	at org.testng.internal.MethodInvocationHelper.invokeMethod(MethodInvocationHelper.java:85)
	at org.testng.internal.Invoker.invokeMethod(Invoker.java:639)
	at org.testng.internal.Invoker.retryFailed(Invoker.java:963)
	at org.testng.internal.Invoker.invokeTestMethods(Invoker.java:1142)
	at org.testng.internal.TestMethodWorker.invokeTestMethods(TestMethodWorker.java:125)
	at org.testng.internal.TestMethodWorker.run(TestMethodWorker.java:108)
	at org.testng.TestRunner.privateRun(TestRunner.java:774)
	at org.testng.TestRunner.run(TestRunner.java:624)
	at org.testng.SuiteRunner.runTest(SuiteRunner.java:359)
	at org.testng.SuiteRunner.runSequentially(SuiteRunner.java:354)
	at org.testng.SuiteRunner.privateRun(SuiteRunner.java:312)
	at org.testng.SuiteRunner.run(SuiteRunner.java:261)
	at org.testng.SuiteRunnerWorker.runSuite(SuiteRunnerWorker.java:52)
	at org.testng.SuiteRunnerWorker.run(SuiteRunnerWorker.java:86)
	at org.testng.TestNG.runSuitesSequentially(TestNG.java:1215)
	at org.testng.TestNG.runSuitesLocally(TestNG.java:1140)
	at org.testng.TestNG.run(TestNG.java:1048)
	at org.testng.remote.AbstractRemoteTestNG.run(AbstractRemoteTestNG.java:126)
	at org.testng.remote.RemoteTestNG.initAndRun(RemoteTestNG.java:152)
	at org.testng.remote.RemoteTestNG.main(RemoteTestNG.java:57)
]]>
            </full-stacktrace>
          </exception> <!-- java.lang.AssertionError -->
          <reporter-output>
          </reporter-output>
        </test-method> <!-- homepageTest -->
        <test-method status="PASS" signature="bMethod()[pri:0, instance:retryLogicFailed.retryFailedTest@3884b2]" name="bMethod" is-config="true" duration-ms="1" started-at="2020-04-05T01:24:27Z" finished-at="2020-04-05T01:24:27Z">
          <reporter-output>
          </reporter-output>
        </test-method> <!-- bMethod -->
        <test-method status="PASS" signature="aMethod()[pri:0, instance:retryLogicFailed.retryFailedTest@3884b2]" name="aMethod" is-config="true" duration-ms="0" started-at="2020-04-05T01:24:27Z" finished-at="2020-04-05T01:24:27Z">
          <reporter-output>
          </reporter-output>
        </test-method> <!-- aMethod -->
        <test-method status="SKIP" signature="loginTest()[pri:0, instance:retryLogicFailed.retryFailedTest@3884b2]" name="loginTest" duration-ms="1" started-at="2020-04-05T01:24:27Z" finished-at="2020-04-05T01:24:27Z">
          <exception class="java.lang.AssertionError">
            <message>
              <![CDATA[expected [true] but found [false]]]>
            </message>
            <full-stacktrace>
              <![CDATA[java.lang.AssertionError: expected [true] but found [false]
	at org.testng.Assert.fail(Assert.java:94)
	at org.testng.Assert.failNotEquals(Assert.java:496)
	at org.testng.Assert.assertTrue(Assert.java:42)
	at org.testng.Assert.assertTrue(Assert.java:52)
	at retryLogicFailed.retryFailedTest.loginTest(retryFailedTest.java:24)
	at sun.reflect.NativeMethodAccessorImpl.invoke0(Native Method)
	at sun.reflect.NativeMethodAccessorImpl.invoke(Unknown Source)
	at sun.reflect.DelegatingMethodAccessorImpl.invoke(Unknown Source)
	at java.lang.reflect.Method.invoke(Unknown Source)
	at org.testng.internal.MethodInvocationHelper.invokeMethod(MethodInvocationHelper.java:85)
	at org.testng.internal.Invoker.invokeMethod(Invoker.java:639)
	at org.testng.internal.Invoker.invokeTestMethod(Invoker.java:816)
	at org.testng.internal.Invoker.invokeTestMethods(Invoker.java:1124)
	at org.testng.internal.TestMethodWorker.invokeTestMethods(TestMethodWorker.java:125)
	at org.testng.internal.TestMethodWorker.run(TestMethodWorker.java:108)
	at org.testng.TestRunner.privateRun(TestRunner.java:774)
	at org.testng.TestRunner.run(TestRunner.java:624)
	at org.testng.SuiteRunner.runTest(SuiteRunner.java:359)
	at org.testng.SuiteRunner.runSequentially(SuiteRunner.java:354)
	at org.testng.SuiteRunner.privateRun(SuiteRunner.java:312)
	at org.testng.SuiteRunner.run(SuiteRunner.java:261)
	at org.testng.SuiteRunnerWorker.runSuite(SuiteRunnerWorker.java:52)
	at org.testng.SuiteRunnerWorker.run(SuiteRunnerWorker.java:86)
	at org.testng.TestNG.runSuitesSequentially(TestNG.java:1215)
	at org.testng.TestNG.runSuitesLocally(TestNG.java:1140)
	at org.testng.TestNG.run(TestNG.java:1048)
	at org.testng.remote.AbstractRemoteTestNG.run(AbstractRemoteTestNG.java:126)
	at org.testng.remote.RemoteTestNG.initAndRun(RemoteTestNG.java:152)
	at org.testng.remote.RemoteTestNG.main(RemoteTestNG.java:57)
]]>
            </full-stacktrace>
          </exception> <!-- java.lang.AssertionError -->
          <reporter-output>
          </reporter-output>
        </test-method> <!-- loginTest -->
        <test-method status="PASS" signature="aMethod()[pri:0, instance:retryLogicFailed.retryFailedTest@3884b2]" name="aMethod" is-config="true" duration-ms="0" started-at="2020-04-05T01:24:27Z" finished-at="2020-04-05T01:24:27Z">
          <reporter-output>
          </reporter-output>
        </test-method> <!-- aMethod -->
        <test-method status="PASS" signature="bMethod()[pri:0, instance:retryLogicFailed.retryFailedTest@3884b2]" name="bMethod" is-config="true" duration-ms="0" started-at="2020-04-05T01:24:27Z" finished-at="2020-04-05T01:24:27Z">
          <reporter-output>
          </reporter-output>
        </test-method> <!-- bMethod -->
        <test-method status="SKIP" signature="loginTest()[pri:0, instance:retryLogicFailed.retryFailedTest@3884b2]" name="loginTest" duration-ms="1" started-at="2020-04-05T01:24:27Z" finished-at="2020-04-05T01:24:27Z">
          <exception class="java.lang.AssertionError">
            <message>
              <![CDATA[expected [true] but found [false]]]>
            </message>
            <full-stacktrace>
              <![CDATA[java.lang.AssertionError: expected [true] but found [false]
	at org.testng.Assert.fail(Assert.java:94)
	at org.testng.Assert.failNotEquals(Assert.java:496)
	at org.testng.Assert.assertTrue(Assert.java:42)
	at org.testng.Assert.assertTrue(Assert.java:52)
	at retryLogicFailed.retryFailedTest.loginTest(retryFailedTest.java:24)
	at sun.reflect.NativeMethodAccessorImpl.invoke0(Native Method)
	at sun.reflect.NativeMethodAccessorImpl.invoke(Unknown Source)
	at sun.reflect.DelegatingMethodAccessorImpl.invoke(Unknown Source)
	at java.lang.reflect.Method.invoke(Unknown Source)
	at org.testng.internal.MethodInvocationHelper.invokeMethod(MethodInvocationHelper.java:85)
	at org.testng.internal.Invoker.invokeMethod(Invoker.java:639)
	at org.testng.internal.Invoker.retryFailed(Invoker.java:963)
	at org.testng.internal.Invoker.invokeTestMethods(Invoker.java:1142)
	at org.testng.internal.TestMethodWorker.invokeTestMethods(TestMethodWorker.java:125)
	at org.testng.internal.TestMethodWorker.run(TestMethodWorker.java:108)
	at org.testng.TestRunner.privateRun(TestRunner.java:774)
	at org.testng.TestRunner.run(TestRunner.java:624)
	at org.testng.SuiteRunner.runTest(SuiteRunner.java:359)
	at org.testng.SuiteRunner.runSequentially(SuiteRunner.java:354)
	at org.testng.SuiteRunner.privateRun(SuiteRunner.java:312)
	at org.testng.SuiteRunner.run(SuiteRunner.java:261)
	at org.testng.SuiteRunnerWorker.runSuite(SuiteRunnerWorker.java:52)
	at org.testng.SuiteRunnerWorker.run(SuiteRunnerWorker.java:86)
	at org.testng.TestNG.runSuitesSequentially(TestNG.java:1215)
	at org.testng.TestNG.runSuitesLocally(TestNG.java:1140)
	at org.testng.TestNG.run(TestNG.java:1048)
	at org.testng.remote.AbstractRemoteTestNG.run(AbstractRemoteTestNG.java:126)
	at org.testng.remote.RemoteTestNG.initAndRun(RemoteTestNG.java:152)
	at org.testng.remote.RemoteTestNG.main(RemoteTestNG.java:57)
]]>
            </full-stacktrace>
          </exception> <!-- java.lang.AssertionError -->
          <reporter-output>
          </reporter-output>
        </test-method> <!-- loginTest -->
        <test-method status="PASS" signature="aMethod()[pri:0, instance:retryLogicFailed.retryFailedTest@3884b2]" name="aMethod" is-config="true" duration-ms="1" started-at="2020-04-05T01:24:27Z" finished-at="2020-04-05T01:24:27Z">
          <reporter-output>
          </reporter-output>
        </test-method> <!-- aMethod -->
        <test-method status="PASS" signature="bMethod()[pri:0, instance:retryLogicFailed.retryFailedTest@3884b2]" name="bMethod" is-config="true" duration-ms="1" started-at="2020-04-05T01:24:27Z" finished-at="2020-04-05T01:24:27Z">
          <reporter-output>
          </reporter-output>
        </test-method> <!-- bMethod -->
        <test-method status="SKIP" signature="loginTest()[pri:0, instance:retryLogicFailed.retryFailedTest@3884b2]" name="loginTest" duration-ms="1" started-at="2020-04-05T01:24:27Z" finished-at="2020-04-05T01:24:27Z">
          <exception class="java.lang.AssertionError">
            <message>
              <![CDATA[expected [true] but found [false]]]>
            </message>
            <full-stacktrace>
              <![CDATA[java.lang.AssertionError: expected [true] but found [false]
	at org.testng.Assert.fail(Assert.java:94)
	at org.testng.Assert.failNotEquals(Assert.java:496)
	at org.testng.Assert.assertTrue(Assert.java:42)
	at org.testng.Assert.assertTrue(Assert.java:52)
	at retryLogicFailed.retryFailedTest.loginTest(retryFailedTest.java:24)
	at sun.reflect.NativeMethodAccessorImpl.invoke0(Native Method)
	at sun.reflect.NativeMethodAccessorImpl.invoke(Unknown Source)
	at sun.reflect.DelegatingMethodAccessorImpl.invoke(Unknown Source)
	at java.lang.reflect.Method.invoke(Unknown Source)
	at org.testng.internal.MethodInvocationHelper.invokeMethod(MethodInvocationHelper.java:85)
	at org.testng.internal.Invoker.invokeMethod(Invoker.java:639)
	at org.testng.internal.Invoker.retryFailed(Invoker.java:963)
	at org.testng.internal.Invoker.invokeTestMethods(Invoker.java:1142)
	at org.testng.internal.TestMethodWorker.invokeTestMethods(TestMethodWorker.java:125)
	at org.testng.internal.TestMethodWorker.run(TestMethodWorker.java:108)
	at org.testng.TestRunner.privateRun(TestRunner.java:774)
	at org.testng.TestRunner.run(TestRunner.java:624)
	at org.testng.SuiteRunner.runTest(SuiteRunner.java:359)
	at org.testng.SuiteRunner.runSequentially(SuiteRunner.java:354)
	at org.testng.SuiteRunner.privateRun(SuiteRunner.java:312)
	at org.testng.SuiteRunner.run(SuiteRunner.java:261)
	at org.testng.SuiteRunnerWorker.runSuite(SuiteRunnerWorker.java:52)
	at org.testng.SuiteRunnerWorker.run(SuiteRunnerWorker.java:86)
	at org.testng.TestNG.runSuitesSequentially(TestNG.java:1215)
	at org.testng.TestNG.runSuitesLocally(TestNG.java:1140)
	at org.testng.TestNG.run(TestNG.java:1048)
	at org.testng.remote.AbstractRemoteTestNG.run(AbstractRemoteTestNG.java:126)
	at org.testng.remote.RemoteTestNG.initAndRun(RemoteTestNG.java:152)
	at org.testng.remote.RemoteTestNG.main(RemoteTestNG.java:57)
]]>
            </full-stacktrace>
          </exception> <!-- java.lang.AssertionError -->
          <reporter-output>
          </reporter-output>
        </test-method> <!-- loginTest -->
        <test-method status="SKIP" signature="loginTest()[pri:0, instance:retryLogicFailed.retryFailedTest@3884b2]" name="loginTest" duration-ms="1" started-at="2020-04-05T01:24:27Z" finished-at="2020-04-05T01:24:27Z">
          <exception class="java.lang.AssertionError">
            <message>
              <![CDATA[expected [true] but found [false]]]>
            </message>
            <full-stacktrace>
              <![CDATA[java.lang.AssertionError: expected [true] but found [false]
	at org.testng.Assert.fail(Assert.java:94)
	at org.testng.Assert.failNotEquals(Assert.java:496)
	at org.testng.Assert.assertTrue(Assert.java:42)
	at org.testng.Assert.assertTrue(Assert.java:52)
	at retryLogicFailed.retryFailedTest.loginTest(retryFailedTest.java:24)
	at sun.reflect.NativeMethodAccessorImpl.invoke0(Native Method)
	at sun.reflect.NativeMethodAccessorImpl.invoke(Unknown Source)
	at sun.reflect.DelegatingMethodAccessorImpl.invoke(Unknown Source)
	at java.lang.reflect.Method.invoke(Unknown Source)
	at org.testng.internal.MethodInvocationHelper.invokeMethod(MethodInvocationHelper.java:85)
	at org.testng.internal.Invoker.invokeMethod(Invoker.java:639)
	at org.testng.internal.Invoker.retryFailed(Invoker.java:963)
	at org.testng.internal.Invoker.invokeTestMethods(Invoker.java:1142)
	at org.testng.internal.TestMethodWorker.invokeTestMethods(TestMethodWorker.java:125)
	at org.testng.internal.TestMethodWorker.run(TestMethodWorker.java:108)
	at org.testng.TestRunner.privateRun(TestRunner.java:774)
	at org.testng.TestRunner.run(TestRunner.java:624)
	at org.testng.SuiteRunner.runTest(SuiteRunner.java:359)
	at org.testng.SuiteRunner.runSequentially(SuiteRunner.java:354)
	at org.testng.SuiteRunner.privateRun(SuiteRunner.java:312)
	at org.testng.SuiteRunner.run(SuiteRunner.java:261)
	at org.testng.SuiteRunnerWorker.runSuite(SuiteRunnerWorker.java:52)
	at org.testng.SuiteRunnerWorker.run(SuiteRunnerWorker.java:86)
	at org.testng.TestNG.runSuitesSequentially(TestNG.java:1215)
	at org.testng.TestNG.runSuitesLocally(TestNG.java:1140)
	at org.testng.TestNG.run(TestNG.java:1048)
	at org.testng.remote.AbstractRemoteTestNG.run(AbstractRemoteTestNG.java:126)
	at org.testng.remote.RemoteTestNG.initAndRun(RemoteTestNG.java:152)
	at org.testng.remote.RemoteTestNG.main(RemoteTestNG.java:57)
]]>
            </full-stacktrace>
          </exception> <!-- java.lang.AssertionError -->
          <reporter-output>
          </reporter-output>
        </test-method> <!-- loginTest -->
        <test-method status="PASS" signature="aMethod()[pri:0, instance:retryLogicFailed.retryFailedTest@3884b2]" name="aMethod" is-config="true" duration-ms="0" started-at="2020-04-05T01:24:27Z" finished-at="2020-04-05T01:24:27Z">
          <reporter-output>
          </reporter-output>
        </test-method> <!-- aMethod -->
        <test-method status="PASS" signature="bMethod()[pri:0, instance:retryLogicFailed.retryFailedTest@3884b2]" name="bMethod" is-config="true" duration-ms="0" started-at="2020-04-05T01:24:27Z" finished-at="2020-04-05T01:24:27Z">
          <reporter-output>
          </reporter-output>
        </test-method> <!-- bMethod -->
        <test-method status="PASS" signature="bMethod()[pri:0, instance:retryLogicFailed.retryFailedTest@3884b2]" name="bMethod" is-config="true" duration-ms="1" started-at="2020-04-05T01:24:27Z" finished-at="2020-04-05T01:24:27Z">
          <reporter-output>
          </reporter-output>
        </test-method> <!-- bMethod -->
        <test-method status="PASS" signature="aMethod()[pri:0, instance:retryLogicFailed.retryFailedTest@3884b2]" name="aMethod" is-config="true" duration-ms="0" started-at="2020-04-05T01:24:27Z" finished-at="2020-04-05T01:24:27Z">
          <reporter-output>
          </reporter-output>
        </test-method> <!-- aMethod -->
        <test-method status="FAIL" signature="loginTest()[pri:0, instance:retryLogicFailed.retryFailedTest@3884b2]" name="loginTest" duration-ms="0" started-at="2020-04-05T01:24:27Z" finished-at="2020-04-05T01:24:27Z">
          <exception class="java.lang.AssertionError">
            <message>
              <![CDATA[expected [true] but found [false]]]>
            </message>
            <full-stacktrace>
              <![CDATA[java.lang.AssertionError: expected [true] but found [false]
	at org.testng.Assert.fail(Assert.java:94)
	at org.testng.Assert.failNotEquals(Assert.java:496)
	at org.testng.Assert.assertTrue(Assert.java:42)
	at org.testng.Assert.assertTrue(Assert.java:52)
	at retryLogicFailed.retryFailedTest.loginTest(retryFailedTest.java:24)
	at sun.reflect.NativeMethodAccessorImpl.invoke0(Native Method)
	at sun.reflect.NativeMethodAccessorImpl.invoke(Unknown Source)
	at sun.reflect.DelegatingMethodAccessorImpl.invoke(Unknown Source)
	at java.lang.reflect.Method.invoke(Unknown Source)
	at org.testng.internal.MethodInvocationHelper.invokeMethod(MethodInvocationHelper.java:85)
	at org.testng.internal.Invoker.invokeMethod(Invoker.java:639)
	at org.testng.internal.Invoker.retryFailed(Invoker.java:963)
	at org.testng.internal.Invoker.invokeTestMethods(Invoker.java:1142)
	at org.testng.internal.TestMethodWorker.invokeTestMethods(TestMethodWorker.java:125)
	at org.testng.internal.TestMethodWorker.run(TestMethodWorker.java:108)
	at org.testng.TestRunner.privateRun(TestRunner.java:774)
	at org.testng.TestRunner.run(TestRunner.java:624)
	at org.testng.SuiteRunner.runTest(SuiteRunner.java:359)
	at org.testng.SuiteRunner.runSequentially(SuiteRunner.java:354)
	at org.testng.SuiteRunner.privateRun(SuiteRunner.java:312)
	at org.testng.SuiteRunner.run(SuiteRunner.java:261)
	at org.testng.SuiteRunnerWorker.runSuite(SuiteRunnerWorker.java:52)
	at org.testng.SuiteRunnerWorker.run(SuiteRunnerWorker.java:86)
	at org.testng.TestNG.runSuitesSequentially(TestNG.java:1215)
	at org.testng.TestNG.runSuitesLocally(TestNG.java:1140)
	at org.testng.TestNG.run(TestNG.java:1048)
	at org.testng.remote.AbstractRemoteTestNG.run(AbstractRemoteTestNG.java:126)
	at org.testng.remote.RemoteTestNG.initAndRun(RemoteTestNG.java:152)
	at org.testng.remote.RemoteTestNG.main(RemoteTestNG.java:57)
]]>
            </full-stacktrace>
          </exception> <!-- java.lang.AssertionError -->
          <reporter-output>
          </reporter-output>
        </test-method> <!-- loginTest -->
        <test-method status="PASS" signature="aMethod()[pri:0, instance:retryLogicFailed.retryFailedTest@3884b2]" name="aMethod" is-config="true" duration-ms="0" started-at="2020-04-05T01:24:27Z" finished-at="2020-04-05T01:24:27Z">
          <reporter-output>
          </reporter-output>
        </test-method> <!-- aMethod -->
        <test-method status="PASS" signature="bMethod()[pri:0, instance:retryLogicFailed.retryFailedTest@3884b2]" name="bMethod" is-config="true" duration-ms="1" started-at="2020-04-05T01:24:27Z" finished-at="2020-04-05T01:24:27Z">
          <reporter-output>
          </reporter-output>
        </test-method> <!-- bMethod -->
        <test-method status="PASS" signature="verifyTitleTest()[pri:0, instance:retryLogicFailed.retryFailedTest@3884b2]" name="verifyTitleTest" duration-ms="0" started-at="2020-04-05T01:24:27Z" finished-at="2020-04-05T01:24:27Z">
          <reporter-output>
          </reporter-output>
        </test-method> <!-- verifyTitleTest -->
        <test-method status="PASS" signature="aMethod()[pri:0, instance:retryLogicFailed.retryFailedTest@3884b2]" name="aMethod" is-config="true" duration-ms="0" started-at="2020-04-05T01:24:27Z" finished-at="2020-04-05T01:24:27Z">
          <reporter-output>
          </reporter-output>
        </test-method> <!-- aMethod -->
      </class> <!-- retryLogicFailed.retryFailedTest -->
    </test> <!-- Test -->
  </suite> <!-- Suite -->
</testng-results>
